Workbook

Sheet Control
A1: Project No. & Contract No. | B1: AZAC169 - Natref Hybird Project | D1: Last Number | E1: 000929
A2: Work Pack | B2: WP1 | D2: Work Presence
D3: Piping | E3: 1
D4: Fabrication | E4: 1
D5: Erection | E5: 1
D6: Support | E6: 1
D7: Operating Temperature | E7: 40
D8: Insulation Type | E8: None
D9: Line Number | E9: N142703-L-1"
D10: Sheet Number | E10: 1
D11: Revision Number | E11: 01

Sheet Pipe
I1: =TEXT(E6,"000000")&"-"&SUBSTITUTE(SUBSTITUTE(E8,CHAR(34),""),"/",".")&"-"&TEXT(F8,"000")&"-R"&TEXT(G8,"00") -> 000930-N142703-L-1-001-R01
D3: Picking Ticket | F3: Page of
A5: Craft | C5: Requested No. | D5: Paint Spec: | E5: Picking Ticket No. | F5: Date | H5: OP TEMP | I5: =Control!E7 -> 40
A6: Pipe | C6: {=""& _xlfn.TEXTJOIN("",TRUE,IF(ISNUMBER(--MID(Control!B1,_xlfn.SEQUENCE(LEN(Control!B1)),1)), MID(Control!B1,_xlfn.SEQUENCE(LEN(Control!B1)),1),"")) & "-"} -> 169- | D6: =_xlfn.LET(_xlpm.isPipe, _xlfn.SHEET()=2, _xlpm.firstCode, IF(OR(I6="None",I6=""), IF(I5<=90,"2A", IF(I5<=120,"2B", IF(I5<=200,"2C", IF(I5<=400,"2D", IF(I5<=650,"2I",""))))), IF(I5<=150,"2E", IF(I5<=650,"2I",""))), _xlpm.secondCode, IF(OR(I6="None",I6=""), IF(I5<=90,"5A", IF(I5<=200,"5B","")), IF(I5<=150,"5C", IF(I5<=650,"2I",""))), IF(_xlpm.isPipe, _xlpm.firstCode, _xlpm.firstCode&"/"&_xlpm.secondCode)) -> 2A | E6: =IF(Control!E3=1,TEXT(Control!E1+1,"000000"), "") -> 000930 | H6: Insulation type | I6: =Control!E8 -> None
A7: Project No. & Contract No. | D7: Work Pack | E7: Drawing No. | F7: Sht | G7: Rev
A8: AZAC169 - Natref Hybird Project | D8: =Control!B2 -> WP1 | E8: =(Control!E9) & IF(Control!E8<>"none","-"&Control!E8,"") -> N142703-L-1" | F8: =Control!E10 -> 1 | G8: =Control!E11 -> 01
A9: Drawing Item No. | B9: Item Code or Tag No, | C9: Size | D9: Quantity Required | E9: Material Description | F9: Quantity Issued | G9: Heat Number
A10: 1 | B10: 0356032 | C10: 1" | D10: 0.2m | E10: =IFERROR(INDEX('Item codes'!B1:B261,MATCH(B10,'Item codes'!A1:A261,0)),"") -> PIPE SCH 80 SMLS STL A106 B
E11: =IFERROR(INDEX('Item codes'!B1:B261,MATCH(B11,'Item codes'!A1:A261,0)),"")
E12: =IFERROR(INDEX('Item codes'!B1:B261,MATCH(B12,'Item codes'!A1:A261,0)),"")
E13: =IFERROR(INDEX('Item codes'!B1:B261,MATCH(B13,'Item codes'!A1:A261,0)),"")
E14: =IFERROR(INDEX('Item codes'!B1:B261,MATCH(B14,'Item codes'!A1:A261,0)),"")
E15: =IFERROR(INDEX('Item codes'!B1:B261,MATCH(B15,'Item codes'!A1:A261,0)),"")
E16: =IFERROR(INDEX('Item codes'!B1:B261,MATCH(B16,'Item codes'!A1:A261,0)),"")
E17: =IFERROR(INDEX('Item codes'!B1:B261,MATCH(B17,'Item codes'!A1:A261,0)),"")
E18: =IFERROR(INDEX('Item codes'!B1:B261,MATCH(B18,'Item codes'!A1:A261,0)),"")
E19: =IFERROR(INDEX('Item codes'!B1:B261,MATCH(B19,'Item codes'!A1:A261,0)),"")
E20: =IFERROR(INDEX('Item codes'!B1:B261,MATCH(B20,'Item codes'!A1:A261,0)),"")
E21: =IFERROR(INDEX('Item codes'!B1:B261,MATCH(B21,'Item codes'!A1:A261,0)),"")
E22: =IFERROR(INDEX('Item codes'!B1:B261,MATCH(B22,'Item codes'!A1:A261,0)),"")
E23: =IFERROR(INDEX('Item codes'!B1:B261,MATCH(B23,'Item codes'!A1:A261,0)),"")
E24: =IFERROR(INDEX('Item codes'!B1:B261,MATCH(B24,'Item codes'!A1:A261,0)),"")
E25: =IFERROR(INDEX('Item codes'!B1:B261,MATCH(B25,'Item codes'!A1:A261,0)),"")
E26: =IFERROR(INDEX('Item codes'!B1:B261,MATCH(B26,'Item codes'!A1:A261,0)),"")
E27: =IFERROR(INDEX('Item codes'!B1:B261,MATCH(B27,'Item codes'!A1:A261,0)),"")
E28: =IFERROR(INDEX('Item codes'!B1:B261,MATCH(B28,'Item codes'!A1:A261,0)),"")
E29: =IFERROR(INDEX('Item codes'!B1:B261,MATCH(B29,'Item codes'!A1:A261,0)),"")
E30: =IFERROR(INDEX('Item codes'!B1:B261,MATCH(B30,'Item codes'!A1:A261,0)),"")
E31: =IFERROR(INDEX('Item codes'!B1:B261,MATCH(B31,'Item codes'!A1:A261,0)),"")
E32: =IFERROR(INDEX('Item codes'!B1:B261,MATCH(B32,'Item codes'!A1:A261,0)),"")
E33: =IFERROR(INDEX('Item codes'!B1:B261,MATCH(B33,'Item codes'!A1:A261,0)),"")
A34: Signature and Date
A35: Approved: | E35: Issued By: | F35: Received By:

Sheet Fabrication
I1: =TEXT(E6,"000000")&"-"&SUBSTITUTE(SUBSTITUTE(E8,CHAR(34),""),"/",".")&"-"&TEXT(F8,"000")&"-R"&TEXT(G8,"00") -> 000931-N142703-L-1-001-R01
D3: Picking Ticket | F3: Page of
A5: Craft | C5: Requested No. | D5: Paint Spec: | E5: Picking Ticket No. | F5: Date | H5: OP TEMP | I5: =Pipe!I5 -> 40
A6: Fabrication | C6: =Pipe!C6 -> 169- | D6: =_xlfn.LET(_xlpm.isPipe, _xlfn.SHEET()=2, _xlpm.firstCode, IF(OR(I6="None",I6=""), IF(I5<=90,"2A", IF(I5<=120,"2B", IF(I5<=200,"2C", IF(I5<=400,"2B", IF(I5<=650,"2I",""))))),IF(I5<=150,"2E", IF(I5<=650,"2I",""))), _xlpm.secondCode, IF(OR(I6="None",I6=""), IF(I5<=90,"5A", IF(I5<=200,"5B","2I")), IF(I5<=150,"5C", IF(I5<=650,"2I",""))), IF(_xlpm.isPipe, _xlpm.firstCode, _xlpm.firstCode&"/"&_xlpm.secondCode)) -> 2A/5A | E6: =IF(Control!E4=1,TEXT(Control!E1+Control!E3+1,"000000"), "") -> 000931 | H6: Insulation type | I6: =Pipe!I6 -> None
A7: Project No. & Contract No. | D7: Work Pack | E7: Drawing No. | F7: Sht | G7: Rev
A8: =Pipe!A8 -> AZAC169 - Natref Hybird Project | B8: =Pipe!B8 -> 0 | C8: =Pipe!C8 -> 0 | D8: =Pipe!D8 -> WP1 | E8: =Pipe!E8 -> N142703-L-1" | F8: =Pipe!F8 -> 1 | G8: =Pipe!G8 -> 01
A9: Drawing Item No. | B9: Item Code or Tag No, | C9: Size | D9: Quantity Required | E9: Material Description | F9: Quantity Issued | G9: Heat Number
A10: 1 | B10: 0374285 | C10: 1" | D10: 1 | E10: =IFERROR(INDEX('Item codes'!B1:B261,MATCH(B10,'Item codes'!A1:A261,0)),"") -> RED TEE SCH XS STL A234 WPB
A11: 2 | B11: 0554396 | C11: 1" | D11: 1 | E11: =IFERROR(INDEX('Item codes'!B2:B262,MATCH(B11,'Item codes'!A2:A262,0)),"") -> FLANGE WN CL 150 RF XS BORE A105
A12: 3 | B12: 0554627 | C12: 1" | D12: 2 | E12: =IFERROR(INDEX('Item codes'!B3:B263,MATCH(B12,'Item codes'!A3:A263,0)),"") -> FLANGE WN CL 300 RF XS BORE STL A105
E13: =IFERROR(INDEX('Item codes'!B4:B264,MATCH(B13,'Item codes'!A4:A264,0)),"")
E14: =IFERROR(INDEX('Item codes'!B5:B265,MATCH(B14,'Item codes'!A5:A265,0)),"")
E15: =IFERROR(INDEX('Item codes'!B6:B266,MATCH(B15,'Item codes'!A6:A266,0)),"")
E16: =IFERROR(INDEX('Item codes'!B7:B267,MATCH(B16,'Item codes'!A7:A267,0)),"")
E17: =IFERROR(INDEX('Item codes'!B8:B268,MATCH(B17,'Item codes'!A8:A268,0)),"")
E18: =IFERROR(INDEX('Item codes'!B9:B269,MATCH(B18,'Item codes'!A9:A269,0)),"")
E19: =IFERROR(INDEX('Item codes'!B10:B270,MATCH(B19,'Item codes'!A10:A270,0)),"")
E20: =IFERROR(INDEX('Item codes'!B11:B271,MATCH(B20,'Item codes'!A11:A271,0)),"")
E21: =IFERROR(INDEX('Item codes'!B12:B272,MATCH(B21,'Item codes'!A12:A272,0)),"")
E22: =IFERROR(INDEX('Item codes'!B13:B273,MATCH(B22,'Item codes'!A13:A273,0)),"")
E23: =IFERROR(INDEX('Item codes'!B14:B274,MATCH(B23,'Item codes'!A14:A274,0)),"")
E24: =IFERROR(INDEX('Item codes'!B15:B275,MATCH(B24,'Item codes'!A15:A275,0)),"")
... E33: =IFERROR(INDEX('Item codes'!B24:B284,MATCH(B33,'Item codes'!A24:A284,0)),"")
A34: Signature and Date
A35: Approved: | E35: Issued By: | F35: Received By:

Sheet Erection
I1: =TEXT(E6,"000000")&"-"&SUBSTITUTE(SUBSTITUTE(E8,CHAR(34),""),"/",".")&"-"&TEXT(F8,"000")&"-R"&TEXT(G8,"00") -> 000932-N142703-L-1-001-R01
D3: Picking Ticket | F3: Page of
A5: Craft | C5: Requested No. | D5: Paint Spec: | E5: Picking Ticket No. | F5: Date | H5: OP TEMP | I5: =Pipe!I5 -> 40
A6: Erection | C6: =Pipe!C6 -> 169- | D6: =_xlfn.LET( _xlpm.isPipe, _xlfn.SHEET()=2, _xlpm.firstCode, IF(OR(I6="None",I6=""), IF(I5<=90,"2A", IF(I5<=120,"2B", IF(I5<=200,"2C", IF(I5<=400,"2D", IF(I5<=650,"2I",""))))), IF(I5<=150,"2E", IF(I5<=650,"2I",""))), _xlpm.secondCode,IF(OR(I6="None",I6=""), IF(I5<=90,"5A", IF(I5<=200,"5B","2I")), IF(I5<=150,"5C", IF(I5<=650,"2I",""))), IF(_xlpm.isPipe, _xlpm.firstCode, _xlpm.firstCode&"/"&_xlpm.secondCode)) -> 2A/5A | E6: =IF(Control!E5=1,TEXT(Control!E1+Control!E3+Control!E4+1,"000000"), "") -> 000932 | H6: Insulation type | I6: =Pipe!I6 -> None
A7: Project No. & Contract No. | D7: Work Pack | E7: Drawing No. | F7: Sht | G7: Rev
A8: =Pipe!A8 -> AZAC169 - Natref Hybird Project | B8: =Pipe!B8 -> 0 | C8: =Pipe!C8 -> 0 | D8: =Pipe!D8 -> WP1 | E8: =Pipe!E8 -> N142703-L-1" | F8: =Pipe!F8 -> 1 | G8: =Pipe!G8 -> 01
A9: Drawing Item No. | B9: Item Code or Tag No, | C9: Size | D9: Quantity Required | E9: Material Description | F9: Quantity Issued | G9: Heat Number
A10: 4 | B10: 0672123 | C10: 2" | D10: 1 | E10: =IFERROR(INDEX('Item codes'!B1:B261,MATCH(B10,'Item codes'!A1:A261,0)),"") -> GASKET CL 150 304 SS SP WND GRAF 4.5 MM THK
A11: 5 | B11: 0672123 | C11: 1" | D11: 1 | E11: =IFERROR(INDEX('Item codes'!B2:B262,MATCH(B11,'Item codes'!A2:A262,0)),"") -> GASKET CL 150 304 SS SP WND GRAF 4.5 MM THK
A12: 6 | B12: 0672151 | C12: 1" | D12: 4 | E12: =IFERROR(INDEX('Item codes'!B3:B263,MATCH(B12,'Item codes'!A3:A263,0)),"") -> GASKET CL 300 304 SS SP WND GRAF 4.5 MM THK
A13: 7 | B13: 0675648 | C13: 5/8x100mm | D13: 16 | E13: =IFERROR(INDEX('Item codes'!B4:B264,MATCH(B13,'Item codes'!A4:A264,0)),"") -> STUD BOLT A193 B7 W/A194 GR 2H NUTS
A14: 8 | B14: 0675648 | C14: 1/2x90mm | D14: 4 | E14: =IFERROR(INDEX('Item codes'!B5:B265,MATCH(B14,'Item codes'!A5:A265,0)),"") -> STUD BOLT A193 B7 W/A194 GR 2H NUTS
A15: 9 | B15: 0615497 | C15: 1" | D15: 1 | E15: =IFERROR(INDEX('Item codes'!B6:B266,MATCH(B15,'Item codes'!A6:A266,0)),"") -> FLANGE BLIND CL 300 RF STL A105
A16: 10 | B16: 0158301 | C16: 1" | D16: 1 | E16: =IFERROR(INDEX('Item codes'!B7:B267,MATCH(B16,'Item codes'!A7:A267,0)),"") -> GATE CL 600 RF STL F6/STEL GRAF BB
A17: 11 | B17: 0158308 | C17: 1" | D17: 1 | E17: =IFERROR(INDEX('Item codes'!B8:B268,MATCH(B17,'Item codes'!A8:A268,0)),"") -> GATE CL 600 RF STL F6/STEL FRAF BB FULL PORT
A18: 12 | B18: 0675648 | C18: 5/8x90mm | D18: 4 | E18: =IFERROR(INDEX('Item codes'!B9:B269,MATCH(B18,'Item codes'!A9:A269,0)),"") -> STUD BOLT A193 B7 W/A194 GR 2H NUTS
E19: =IFERROR(INDEX('Item codes'!B10:B270,MATCH(B19,'Item codes'!A10:A270,0)),"")
E20: =IFERROR(INDEX('Item codes'!B11:B271,MATCH(B20,'Item codes'!A11:A271,0)),"")
E21: =IFERROR(INDEX('Item codes'!B12:B272,MATCH(B21,'Item codes'!A12:A272,0)),"")
E22: =IFERROR(INDEX('Item codes'!B13:B273,MATCH(B22,'Item codes'!A13:A273,0)),"")
E23: =IFERROR(INDEX('Item codes'!B14:B274,MATCH(B23,'Item codes'!A14:A274,0)),"")
E24: =IFERROR(INDEX('Item codes'!B15:B275,MATCH(B24,'Item codes'!A15:A275,0)),"")
E25: =IFERROR(INDEX('Item codes'!B16:B276,MATCH(B25,'Item codes'!A16:A276,0)),"")
E26: =IFERROR(INDEX('Item codes'!B17:B277,MATCH(B26,'Item codes'!A17:A277,0)),"")
E27: =IFERROR(INDEX('Item codes'!B18:B278,MATCH(B27,'Item codes'!A18:A278,0)),"")
E28: =IFERROR(INDEX('Item codes'!B19:B279,MATCH(B28,'Item codes'!A19:A279,0)),"")
E29: =IFERROR(INDEX('Item codes'!B20:B280,MATCH(B29,'Item codes'!A20:A280,0)),"")
E30: =IFERROR(INDEX('Item codes'!B21:B281,MATCH(B30,'Item codes'!A21:A281,0)),"")
... E33: =IFERROR(INDEX('Item codes'!B24:B284,MATCH(B33,'Item codes'!A24:A284,0)),"")
A34: Signature and Date
A35: Approved: | E35: Issued By: | F35: Received By:

Sheet Supports
I1: =TEXT(E6,"000000")&"-"&SUBSTITUTE(SUBSTITUTE(E8,CHAR(34),""),"/",".")&"-"&TEXT(F8,"000")&"-R"&TEXT(G8,"00") -> 000933-N142703-L-1-001-R01
D3: Picking Ticket | F3: Page of
A5: Craft | C5: Requested No. | D5: Paint Spec: | E5: Picking Ticket No. | F5: Date
A6: Supports | C6: =Pipe!C6 -> 169- | D6: N/A | E6: =IF(Control!E6=1,TEXT(Control!E1+Control!E3+Control!E4+Control!E5+1,"000000"), "") -> 000933
A7: Project No. & Contract No. | D7: Work Pack | E7: Drawing No. | F7: Sht | G7: Rev
A8: =Pipe!A8 -> AZAC169 - Natref Hybird Project | B8: =Pipe!B8 -> 0 | C8: =Pipe!C8 -> 0 | D8: =Pipe!D8 -> WP1 | E8: =Pipe!E8 -> N142703-L-1" | F8: =Pipe!F8 -> 1 | G8: =Pipe!G8 -> 01
A9: Drawing Item No. | B9: Item Code or Tag No, | C9: Size | D9: Quantity Required | E9: Material Description | F9: Quantity Issued | G9: Heat Number
A10: 4 | B10: 0805942 | C10: 3" | D10: 2 | E10: =IFERROR(INDEX('Item codes'!B1:B261,MATCH(B10,'Item codes'!A1:A261,0)),"") -> G2 (GUIDE)
E11: =IFERROR(INDEX('Item codes'!B2:B262,MATCH(B11,'Item codes'!A2:A262,0)),"")
E12: =IFERROR(INDEX('Item codes'!B3:B263,MATCH(B12,'Item codes'!A3:A263,0)),"")
E13: =IFERROR(INDEX('Item codes'!B4:B264,MATCH(B13,'Item codes'!A4:A264,0)),"")
E14: =IFERROR(INDEX('Item codes'!B5:B265,MATCH(B14,'Item codes'!A5:A265,0)),"")
E15: =IFERROR(INDEX('Item codes'!B6:B266,MATCH(B15,'Item codes'!A6:A266,0)),"")
E16: =IFERROR(INDEX('Item codes'!B7:B267,MATCH(B16,'Item codes'!A7:A267,0)),"")
E17: =IFERROR(INDEX('Item codes'!B8:B268,MATCH(B17,'Item codes'!A8:A268,0)),"")
E18: =IFERROR(INDEX('Item codes'!B9:B269,MATCH(B18,'Item codes'!A9:A269,0)),"")
E19: =IFERROR(INDEX('Item codes'!B10:B270,MATCH(B19,'Item codes'!A10:A270,0)),"")
E20: =IFERROR(INDEX('Item codes'!B11:B271,MATCH(B20,'Item codes'!A11:A271,0)),"")
E21: =IFERROR(INDEX('Item codes'!B12:B272,MATCH(B21,'Item codes'!A12:A272,0)),"")
E22: =IFERROR(INDEX('Item codes'!B13:B273,MATCH(B22,'Item codes'!A13:A273,0)),"")
... E33: =IFERROR(INDEX('Item codes'!B24:B284,MATCH(B33,'Item codes'!A24:A284,0)),"")
A34: Signature and Date
A35: Approved: | E35: Issued By: | F35: Received By:

Sheet Tutorial
I1: =TEXT(E6,"000000")&"-"&SUBSTITUTE(SUBSTITUTE(E8,CHAR(34),""),"/",".")&"-"&TEXT(F8,"000")&"-R"&TEXT(G8,"00") -> 000437-N142641-CZC-1-001-R01
D3: Picking Ticket | F3: Page of
A5: Craft | C5: Requested No. | D5: Paint Spec: | E5: Picking Ticket No. | F5: Date | H5: OP TEMP | I5: 44
A6: Pipe | C6: 169- | D6: =_xlfn.LET(_xlpm.isPipe, _xlfn.SHEET()=1, _xlpm.firstCode, IF(OR(I6="None",I6=""), IF(I5<=90,"2A", IF(I5<=120,"2B", IF(I5<=200,"2C", IF(I5<=400,"2D", IF(I5<=650,"2I",""))))), IF(I5<=150,"2E", IF(I5<=650,"2I",""))), _xlpm.secondCode, IF(OR(I6="None",I6=""), IF(I5<=90,"5A", IF(I5<=200,"5B","")), IF(I5<=150,"5C", IF(I5<=650,"2I",""))), IF(_xlpm.isPipe, _xlpm.firstCode, _xlpm.firstCode&"/"&_xlpm.secondCode)) -> 2A/5A | E6: 000437 | H6: Insulation type | I6: None
A7: Project No. & Contract No. | D7: Work Pack | E7: . | F7: Sht | G7: Rev
A8: AZAC169 - Natref Hybird Project | D8: WP1 | E8: N142641-CZC-1" | F8: 1 | G8: 1
A9: Drawing Item No. | B9: Item Code or Tag No, | C9: Size | D9: Quantity Required | E9: Material Description | F9: Quantity Issued | G9: Heat Number
A10: 1 | B10: 0356032 | C10: 1" | D10: 0.3M | E10: =IFERROR(INDEX('Item codes'!B1:B261,MATCH(B10,'Item codes'!A1:A261,0)),"") -> PIPE SCH 80 SMLS STL A106 B
E11: =IFERROR(INDEX('Item codes'!B1:B261,MATCH(B11,'Item codes'!A1:A261,0)),"")
E12: =IFERROR(INDEX('Item codes'!B1:B261,MATCH(B12,'Item codes'!A1:A261,0)),"")
E13: =IFERROR(INDEX('Item codes'!B1:B261,MATCH(B13,'Item codes'!A1:A261,0)),"")
E14: =IFERROR(INDEX('Item codes'!B1:B261,MATCH(B14,'Item codes'!A1:A261,0)),"")
E15: =IFERROR(INDEX('Item codes'!B1:B261,MATCH(B15,'Item codes'!A1:A261,0)),"")
E16: =IFERROR(INDEX('Item codes'!B1:B261,MATCH(B16,'Item codes'!A1:A261,0)),"")
E17: =IFERROR(INDEX('Item codes'!B1:B261,MATCH(B17,'Item codes'!A1:A261,0)),"")
E18: =IFERROR(INDEX('Item codes'!B1:B261,MATCH(B18,'Item codes'!A1:A261,0)),"")
E19: =IFERROR(INDEX('Item codes'!B1:B261,MATCH(B19,'Item codes'!A1:A261,0)),"")
E20: =IFERROR(INDEX('Item codes'!B1:B261,MATCH(B20,'Item codes'!A1:A261,0)),"")
E21: =IFERROR(INDEX('Item codes'!B1:B261,MATCH(B21,'Item codes'!A1:A261,0)),"")
E22: =IFERROR(INDEX('Item codes'!B1:B261,MATCH(B22,'Item codes'!A1:A261,0)),"")
E23: =IFERROR(INDEX('Item codes'!B1:B261,MATCH(B23,'Item codes'!A1:A261,0)),"")
E24: =IFERROR(INDEX('Item codes'!B1:B261,MATCH(B24,'Item codes'!A1:A261,0)),"")
E25: =IFERROR(INDEX('Item codes'!B1:B261,MATCH(B25,'Item codes'!A1:A261,0)),"")
E26: =IFERROR(INDEX('Item codes'!B1:B261,MATCH(B26,'Item codes'!A1:A261,0)),"")
E27: =IFERROR(INDEX('Item codes'!B1:B261,MATCH(B27,'Item codes'!A1:A261,0)),"")
E28: =IFERROR(INDEX('Item codes'!B1:B261,MATCH(B28,'Item codes'!A1:A261,0)),"")
E29: =IFERROR(INDEX('Item codes'!B1:B261,MATCH(B29,'Item codes'!A1:A261,0)),"")
E30: =IFERROR(INDEX('Item codes'!B1:B261,MATCH(B30,'Item codes'!A1:A261,0)),"")
E31: =IFERROR(INDEX('Item codes'!B1:B261,MATCH(B31,'Item codes'!A1:A261,0)),"")
E32: =IFERROR(INDEX('Item codes'!B1:B261,MATCH(B32,'Item codes'!A1:A261,0)),"")
E33: =IFERROR(INDEX('Item codes'!B1:B261,MATCH(B33,'Item codes'!A1:A261,0)),"")
A34: Signature and Date
A35: Approved: | E35: Issued By: | F35: Received By:

Sheet Item codes
A1: 0000514 | B1: GATE 150LB SCRD BRONZE B.S.21
A2: 0061782 | B2: GATE 800LB SW STL. F6/STELLITED. SWB
A3: 0061899 | B3: GATE 800LB SW STL MONEL TRIM
A4: 0062543 | B4: GLOBE 800LB SW STL F6/STELLITED SWB
A5: 0156050 | B5: GATE CL 150 RF C STL #5 TR CL A
A6: 0156061 | B6: GATE CL 150 RF STL F6 GRAF BB
A7: 0156068 | B7: GATE CL 150 RF STL F6 GRAF BB FULL PORT
A8: 0156070 | B8: GATE CL 150 RF STL F6 TRIM NO COP
A9: 0156084 | B9: GATE CL 150 RF STL F6 GRAF FW BB
A10: 0156088 | B10: GATE CL 150 RF STL F6 GRAF FW BB GO
A11: 0156860 | B11: GATE CL 300 RF STL F6 TRIM BB
A12: 0156873 | B12: GATE CL 300 RF STL F6 TRIM FW GO
... A118: 0488676 | B118: CAP SCRD GALV MI SANS 14
A119: 488679 | B119: SOCKET RED SCRD GALV MI SANS 14
A120: 0488682 | B120: RED TEE SCRD GALV MI RED RUN EǪ BR SANS 14
A121: 0488696 | B121: PLUG SǪUARE HEAD SCRD GALV MI SANS 14
A122: 0488703 | B122: UNION SCRD GALV MI SANS 14
A123: 0490533 | B123: CAP CL 3000 SCRD STL A105
A124: 0490553 | B124: CAP CL 3000 SCRD STL A105
A125: 0490554 | B125: COUPLING CL 3000 SCRD STL A105
A126: 0490662 | B126: PLUG SǪUARE HEAD SCRD STL A105
A127: 0503812 | B127: WELDOLET SCH XS STL A105 WPB
A128: 0503812 | B128: WELDOLET SCH XS BW/BE STL A105
A129: 0504635 | B129: WELDOLET SCH 20 STL A105
A130: 0504651 | B130: WELDOLET STD WT STL A105
A131: 0504655 | B131: FLAT WELDOLET STD WT STL A105
... A243: 1001227 | B243: BALL CL 150 FF STL 316 TR FIRE FULL PT
A244: 1001703 | B244: COUPLING CL 3000 SCRD BSP ASTM A105
A245: 1001724 | B245: FLANGE LONG WN CL 600 RF 25.4MM A105 CS
A246: 1002598 | B246: INSULATION FLANGE SET RING GSKT 3mm CL 300
A247: 1004150 | B247: COUPLING HOSE CHICARGO CLAW THRD FEMALE BRASS ASME B,1,20,1
A248: 1004450 | B248: HOSE COUPLING CHICARGO CLAW TYPE UNIVERSAL 2 LUG CONNECTION THREADED NPT FEMALE BRASS W/ NEOPRENE SEAL
A249: 1004451 | B249: HOSE COUPLING MALE SPUD SCRD BSP MI EVERTITE 1055
A250: 1004611 | B250: FLAT WELDOLET SCH 80 STL A105
A251: 1006940 | B251: BALL VALVE CL 600 RF C STL
A252: 1006943 | B252: GATE CL 300 RF C STL #5 TR CL A FULL PORT
A253: 1006945 | B253: GATE CL 600 RF CS WB #5 TR CL A FULL PORT
A254: 1006946 | B254: GATE CL 150 RF C STL #5 TR CL A FULL PORT
A255: - | B255: GATE CL 150 SCRD BRONZE BS 21
A256: - | B256: RED TEE SCRD GALV MI SANS 14
...
